2023-12-08 12:47:32,599 INFO    StreamThr :23767 [internal.py:wandb_internal():86] W&B internal server running at pid: 23767, started at: 2023-12-08 12:47:32.599214
2023-12-08 12:47:32,601 DEBUG   HandlerThread:23767 [handler.py:handle_request():144] handle_request: status
2023-12-08 12:47:32,611 INFO    WriterThread:23767 [datastore.py:open_for_write():85] open: /home/luungoc/Continual Learning/Bert-Adapter/Adapter-BERT/src/wandb/run-20231208_124732-d3ojs05g/run-d3ojs05g.wandb
2023-12-08 12:47:32,611 DEBUG   SenderThread:23767 [sender.py:send():369] send: header
2023-12-08 12:47:32,617 DEBUG   SenderThread:23767 [sender.py:send():369] send: run
2023-12-08 12:47:33,274 ERROR   SenderThread:23767 [internal_api.py:execute():323] 401 response executing GraphQL.
2023-12-08 12:47:33,274 ERROR   SenderThread:23767 [internal_api.py:execute():324] {"errors":[{"message":"user is not logged in","path":["upsertBucket"],"extensions":{"code":"PERMISSION_ERROR"}}],"data":{"upsertBucket":null}}
2023-12-08 12:47:33,274 ERROR   SenderThread:23767 [sender.py:send_run():955] The API key you provided is either invalid or missing.  If the `WANDB_API_KEY` environment variable is set, make sure it is correct. Otherwise, to resolve this issue, you may try running the 'wandb login --relogin' command. If you are using a local server, make sure that you're using the correct hostname. If you're not sure, you can try logging in again using the 'wandb login --relogin --host [hostname]' command.(Error 401: Unauthorized)
Traceback (most recent call last):
  File "/home/luungoc/.local/lib/python3.11/site-packages/wandb/sdk/lib/retry.py", line 131, in __call__
    result = self._call_fn(*args, **kwargs)
             ^^^^^^^^^^^^^^^^^^^^^^^^^^^^^^
  File "/home/luungoc/.local/lib/python3.11/site-packages/wandb/sdk/internal/internal_api.py", line 320, in execute
    return self.client.execute(*args, **kwargs)  # type: ignore
           ^^^^^^^^^^^^^^^^^^^^^^^^^^^^^^^^^^^^
  File "/home/luungoc/.local/lib/python3.11/site-packages/wandb/vendor/gql-0.2.0/wandb_gql/client.py", line 52, in execute
    result = self._get_result(document, *args, **kwargs)
             ^^^^^^^^^^^^^^^^^^^^^^^^^^^^^^^^^^^^^^^^^^^
  File "/home/luungoc/.local/lib/python3.11/site-packages/wandb/vendor/gql-0.2.0/wandb_gql/client.py", line 60, in _get_result
    return self.transport.execute(document, *args, **kwargs)
           ^^^^^^^^^^^^^^^^^^^^^^^^^^^^^^^^^^^^^^^^^^^^^^^^^
  File "/home/luungoc/.local/lib/python3.11/site-packages/wandb/sdk/lib/gql_request.py", line 56, in execute
    request.raise_for_status()
  File "/usr/lib/python3/dist-packages/requests/models.py", line 1021, in raise_for_status
    raise HTTPError(http_error_msg, response=self)
requests.exceptions.HTTPError: 401 Client Error: Unauthorized for url: https://api.wandb.ai/graphql

During handling of the above exception, another exception occurred:

Traceback (most recent call last):
  File "/home/luungoc/.local/lib/python3.11/site-packages/wandb/sdk/internal/sender.py", line 953, in send_run
    self._init_run(run, config_value_dict)
  File "/home/luungoc/.local/lib/python3.11/site-packages/wandb/sdk/internal/sender.py", line 991, in _init_run
    server_run, inserted, server_messages = self._api.upsert_run(
                                            ^^^^^^^^^^^^^^^^^^^^^
  File "/home/luungoc/.local/lib/python3.11/site-packages/wandb/apis/normalize.py", line 73, in wrapper
    raise err
  File "/home/luungoc/.local/lib/python3.11/site-packages/wandb/apis/normalize.py", line 41, in wrapper
    return func(*args, **kwargs)
           ^^^^^^^^^^^^^^^^^^^^^
  File "/home/luungoc/.local/lib/python3.11/site-packages/wandb/sdk/internal/internal_api.py", line 1727, in upsert_run
    response = self.gql(
               ^^^^^^^^^
  File "/home/luungoc/.local/lib/python3.11/site-packages/wandb/sdk/internal/internal_api.py", line 292, in gql
    ret = self._retry_gql(
          ^^^^^^^^^^^^^^^^
  File "/home/luungoc/.local/lib/python3.11/site-packages/wandb/sdk/lib/retry.py", line 147, in __call__
    retry_timedelta_triggered = check_retry_fn(e)
                                ^^^^^^^^^^^^^^^^^
  File "/home/luungoc/.local/lib/python3.11/site-packages/wandb/util.py", line 908, in check_retry_fn
    return fallback_retry_fn(e)
           ^^^^^^^^^^^^^^^^^^^^
  File "/home/luungoc/.local/lib/python3.11/site-packages/wandb/util.py", line 839, in no_retry_auth
    raise AuthenticationError(
wandb.errors.AuthenticationError: The API key you provided is either invalid or missing.  If the `WANDB_API_KEY` environment variable is set, make sure it is correct. Otherwise, to resolve this issue, you may try running the 'wandb login --relogin' command. If you are using a local server, make sure that you're using the correct hostname. If you're not sure, you can try logging in again using the 'wandb login --relogin --host [hostname]' command.(Error 401: Unauthorized)
2023-12-08 12:47:38,294 DEBUG   HandlerThread:23767 [handler.py:handle_request():144] handle_request: status_report
2023-12-08 12:47:43,295 DEBUG   HandlerThread:23767 [handler.py:handle_request():144] handle_request: status_report
2023-12-08 12:47:48,297 DEBUG   HandlerThread:23767 [handler.py:handle_request():144] handle_request: status_report
2023-12-08 12:47:53,297 DEBUG   HandlerThread:23767 [handler.py:handle_request():144] handle_request: status_report
2023-12-08 12:47:58,299 DEBUG   HandlerThread:23767 [handler.py:handle_request():144] handle_request: status_report
2023-12-08 12:48:03,300 DEBUG   HandlerThread:23767 [handler.py:handle_request():144] handle_request: status_report
2023-12-08 12:48:08,301 DEBUG   HandlerThread:23767 [handler.py:handle_request():144] handle_request: status_report
2023-12-08 12:48:13,303 DEBUG   HandlerThread:23767 [handler.py:handle_request():144] handle_request: status_report
2023-12-08 12:48:18,305 DEBUG   HandlerThread:23767 [handler.py:handle_request():144] handle_request: status_report
2023-12-08 12:48:23,306 DEBUG   HandlerThread:23767 [handler.py:handle_request():144] handle_request: status_report
2023-12-08 12:48:28,307 DEBUG   HandlerThread:23767 [handler.py:handle_request():144] handle_request: status_report
2023-12-08 12:48:33,309 DEBUG   HandlerThread:23767 [handler.py:handle_request():144] handle_request: status_report
2023-12-08 12:48:38,310 DEBUG   HandlerThread:23767 [handler.py:handle_request():144] handle_request: status_report
2023-12-08 12:48:43,312 DEBUG   HandlerThread:23767 [handler.py:handle_request():144] handle_request: status_report
2023-12-08 12:48:48,314 DEBUG   HandlerThread:23767 [handler.py:handle_request():144] handle_request: status_report
2023-12-08 12:48:53,315 DEBUG   HandlerThread:23767 [handler.py:handle_request():144] handle_request: status_report
2023-12-08 12:48:58,317 DEBUG   HandlerThread:23767 [handler.py:handle_request():144] handle_request: status_report
2023-12-08 12:49:03,319 DEBUG   HandlerThread:23767 [handler.py:handle_request():144] handle_request: status_report
2023-12-08 12:49:08,321 DEBUG   HandlerThread:23767 [handler.py:handle_request():144] handle_request: status_report
2023-12-08 12:49:13,323 DEBUG   HandlerThread:23767 [handler.py:handle_request():144] handle_request: status_report
2023-12-08 12:49:18,324 DEBUG   HandlerThread:23767 [handler.py:handle_request():144] handle_request: status_report
2023-12-08 12:49:23,326 DEBUG   HandlerThread:23767 [handler.py:handle_request():144] handle_request: status_report
2023-12-08 12:49:28,327 DEBUG   HandlerThread:23767 [handler.py:handle_request():144] handle_request: status_report
2023-12-08 12:49:33,329 DEBUG   HandlerThread:23767 [handler.py:handle_request():144] handle_request: status_report
2023-12-08 12:49:38,331 DEBUG   HandlerThread:23767 [handler.py:handle_request():144] handle_request: status_report
2023-12-08 12:49:43,332 DEBUG   HandlerThread:23767 [handler.py:handle_request():144] handle_request: status_report
2023-12-08 12:49:48,334 DEBUG   HandlerThread:23767 [handler.py:handle_request():144] handle_request: status_report
2023-12-08 12:49:53,336 DEBUG   HandlerThread:23767 [handler.py:handle_request():144] handle_request: status_report
2023-12-08 12:49:58,338 DEBUG   HandlerThread:23767 [handler.py:handle_request():144] handle_request: status_report
2023-12-08 12:50:03,339 DEBUG   HandlerThread:23767 [handler.py:handle_request():144] handle_request: status_report
2023-12-08 12:50:08,341 DEBUG   HandlerThread:23767 [handler.py:handle_request():144] handle_request: status_report
2023-12-08 12:50:13,342 DEBUG   HandlerThread:23767 [handler.py:handle_request():144] handle_request: status_report
2023-12-08 12:50:18,343 DEBUG   HandlerThread:23767 [handler.py:handle_request():144] handle_request: status_report
2023-12-08 12:50:23,344 DEBUG   HandlerThread:23767 [handler.py:handle_request():144] handle_request: status_report
2023-12-08 12:50:28,345 DEBUG   HandlerThread:23767 [handler.py:handle_request():144] handle_request: status_report
2023-12-08 12:50:33,347 DEBUG   HandlerThread:23767 [handler.py:handle_request():144] handle_request: status_report
2023-12-08 12:50:38,348 DEBUG   HandlerThread:23767 [handler.py:handle_request():144] handle_request: status_report
2023-12-08 12:50:43,348 DEBUG   HandlerThread:23767 [handler.py:handle_request():144] handle_request: status_report
2023-12-08 12:50:48,351 DEBUG   HandlerThread:23767 [handler.py:handle_request():144] handle_request: status_report
2023-12-08 12:50:53,353 DEBUG   HandlerThread:23767 [handler.py:handle_request():144] handle_request: status_report
2023-12-08 12:50:58,355 DEBUG   HandlerThread:23767 [handler.py:handle_request():144] handle_request: status_report
2023-12-08 12:51:03,356 DEBUG   HandlerThread:23767 [handler.py:handle_request():144] handle_request: status_report
2023-12-08 12:51:08,358 DEBUG   HandlerThread:23767 [handler.py:handle_request():144] handle_request: status_report
2023-12-08 12:51:13,360 DEBUG   HandlerThread:23767 [handler.py:handle_request():144] handle_request: status_report
